Workbook

Sheet 00 - Kapak
A4: TARODAN
A7: Koleksiyoner Modeli & İkinci El Pazarı
A9: KULLANICI KABUL TESTİ (UAT) PLANI
A12: Web Platformu (tarodan.shop) + Admin Paneli (admin.tarodan.shop)
B15: Proje Adı | C15: Tarodan E-Ticaret Platformu
B16: Doküman Türü | C16: Kabul Testi (UAT) — Resmi Onay Belgesi
B17: Versiyon | C17: 1.0
B18: Hazırlayan | C18: Tarodan Geliştirme Ekibi
B19: Müşteri
B20: Hazırlanma Tarihi | C20: 01.05.2026
B21: Test Başlangıç Tarihi
B22: Test Bitiş Tarihi
B23: Toplam Sheet Sayısı | C23: Bkz. 01 - Özet
B24: Toplam Test Senaryosu | C24: Bkz. 01 - Özet
B28: RESMİ ONAY VE TESLİM
B29: İşbu doküman, Tarodan platformunun (web ve admin) tüm fonksiyonel kapsamını kapsayan kabul testi (UAT) senaryolarını içermektedir. Her sheet bir modül/sayfa için detaylı test adımları, beklenen sonuçlar ve sonuç işaretleme alanları sunar. Tüm sheet'lerin sonunda Tarodan ekibi ve Müşteri için ayrı imza alanları bulunmaktadır. Aşağıdaki imzalar, müşterinin platformun belirtilen tüm senaryoları başarıyla geçtiğini ve teslim alındığını teyit eder. Sheet bazlı detay sonuçlar için ilgili sayfayı, modül bazlı özet için '01 - Özet' sayfasını inceleyiniz.
B35: Tarodan — Proje Sorumlusu | F35: Müşteri — Yetkili
B36: Ad Soyad | F36: Ad Soyad
B37: Tarih | F37: Tarih
B38: İmza / Kaşe | F38: İmza / Kaşe

Sheet 01 - Özet
A1: TEST SONUÇLARI ÖZETİ
A4: # | B4: Sheet | C4: Açıklama | D4: Toplam | E4: Geçti | F4: Kaldı | G4: Bloke | H4: Yapılamadı | I4: N/A | J4: Beklemede
A5: 1 | B5: W01 - Auth Kayıt-Giriş | C5: W01 — Kayıt, Giriş ve Çıkış | D5: 13 | E5: =COUNTIF('W01 - Auth Kayıt-Giriş'!H4:H16,"Geçti") | F5: =COUNTIF('W01 - Auth Kayıt-Giriş'!H4:H16,"Kaldı") | G5: =COUNTIF('W01 - Auth Kayıt-Giriş'!H4:H16,"Bloke") | H5: =COUNTIF('W01 - Auth Kayıt-Giriş'!H4:H16,"Yapılamadı") | I5: =COUNTIF('W01 - Auth Kayıt-Giriş'!H4:H16,"N/A") | J5: =COUNTIF('W01 - Auth Kayıt-Giriş'!H4:H16,"Beklemede")
A6: 2 | B6: W02 - Şifre & Email Doğrulama | C6: W02 — Şifre Sıfırlama, E-posta ve OTP Doğrulama | D6: 13 | E6: =COUNTIF('W02 - Şifre & Email Doğrulama'!H4:H16,"Geçti") | F6: =COUNTIF('W02 - Şifre & Email Doğrulama'!H4:H16,"Kaldı") | G6: =COUNTIF('W02 - Şifre & Email Doğrulama'!H4:H16,"Bloke") | H6: =COUNTIF('W02 - Şifre & Email Doğrulama'!H4:H16,"Yapılamadı") | I6: =COUNTIF('W02 - Şifre & Email Doğrulama'!H4:H16,"N/A") | J6: =COUNTIF('W02 - Şifre & Email Doğrulama'!H4:H16,"Beklemede")
A7: 3 | B7: W03 - Anasayfa & Keşif | C7: W03 — Anasayfa, Listeleme, Arama, Kategori, Marka, Üretici | D7: 14 | E7: =COUNTIF('W03 - Anasayfa & Keşif'!H4:H17,"Geçti") | F7: =COUNTIF('W03 - Anasayfa & Keşif'!H4:H17,"Kaldı") | G7: =COUNTIF('W03 - Anasayfa & Keşif'!H4:H17,"Bloke") | H7: =COUNTIF('W03 - Anasayfa & Keşif'!H4:H17,"Yapılamadı") | I7: =COUNTIF('W03 - Anasayfa & Keşif'!H4:H17,"N/A") | J7: =COUNTIF('W03 - Anasayfa & Keşif'!H4:H17,"Beklemede")
A8: 4 | B8: W04 - Ürün Detay | C8: W04 — Ürün Detay Sayfası | D8: 14 | E8: =COUNTIF('W04 - Ürün Detay'!H4:H17,"Geçti") | F8: =COUNTIF('W04 - Ürün Detay'!H4:H17,"Kaldı") | G8: =COUNTIF('W04 - Ürün Detay'!H4:H17,"Bloke") | H8: =COUNTIF('W04 - Ürün Detay'!H4:H17,"Yapılamadı") | I8: =COUNTIF('W04 - Ürün Detay'!H4:H17,"N/A") | J8: =COUNTIF('W04 - Ürün Detay'!H4:H17,"Beklemede")
A9: 5 | B9: W05 - Sepet | C9: W05 — Sepet İşlemleri | D9: 10 | E9: =COUNTIF('W05 - Sepet'!H4:H13,"Geçti") | F9: =COUNTIF('W05 - Sepet'!H4:H13,"Kaldı") | G9: =COUNTIF('W05 - Sepet'!H4:H13,"Bloke") | H9: =COUNTIF('W05 - Sepet'!H4:H13,"Yapılamadı") | I9: =COUNTIF('W05 - Sepet'!H4:H13,"N/A") | J9: =COUNTIF('W05 - Sepet'!H4:H13,"Beklemede")
A10: 6 | B10: W06 - Misafir Checkout | C10: W06 — Misafir Checkout Akışı (E-posta OTP) | D10: 8 | E10: =COUNTIF('W06 - Misafir Checkout'!H4:H11,"Geçti") | F10: =COUNTIF('W06 - Misafir Checkout'!H4:H11,"Kaldı") | G10: =COUNTIF('W06 - Misafir Checkout'!H4:H11,"Bloke") | H10: =COUNTIF('W06 - Misafir Checkout'!H4:H11,"Yapılamadı") | I10: =COUNTIF('W06 - Misafir Checkout'!H4:H11,"N/A") | J10: =COUNTIF('W06 - Misafir Checkout'!H4:H11,"Beklemede")
A11: 7 | B11: W07 - Üye Checkout | C11: W07 — Üye Checkout Akışı | D11: 7 | E11: =COUNTIF('W07 - Üye Checkout'!H4:H10,"Geçti") | F11: =COUNTIF('W07 - Üye Checkout'!H4:H10,"Kaldı") | G11: =COUNTIF('W07 - Üye Checkout'!H4:H10,"Bloke") | H11: =COUNTIF('W07 - Üye Checkout'!H4:H10,"Yapılamadı") | I11: =COUNTIF('W07 - Üye Checkout'!H4:H10,"N/A") | J11: =COUNTIF('W07 - Üye Checkout'!H4:H10,"Beklemede")
A12: 8 | B12: W08 - Ödeme PayTR | C12: W08 — PayTR Ödeme Akışı | D12: 8 | E12: =COUNTIF('W08 - Ödeme PayTR'!H4:H11,"Geçti") | F12: =COUNTIF('W08 - Ödeme PayTR'!H4:H11,"Kaldı") | G12: =COUNTIF('W08 - Ödeme PayTR'!H4:H11,"Bloke") | H12: =COUNTIF('W08 - Ödeme PayTR'!H4:H11,"Yapılamadı") | I12: =COUNTIF('W08 - Ödeme PayTR'!H4:H11,"N/A") | J12: =COUNTIF('W08 - Ödeme PayTR'!H4:H11,"Beklemede")
A13: 9 | B13: W09 - Siparişlerim Listesi | C13: W09 — Siparişlerim (Alıcı) Listesi | D13: 6 | E13: =COUNTIF('W09 - Siparişlerim Listesi'!H4:H9,"Geçti") | F13: =COUNTIF('W09 - Siparişlerim Listesi'!H4:H9,"Kaldı") | G13: =COUNTIF('W09 - Siparişlerim Listesi'!H4:H9,"Bloke") | H13: =COUNTIF('W09 - Siparişlerim Listesi'!H4:H9,"Yapılamadı") | I13: =COUNTIF('W09 - Siparişlerim Listesi'!H4:H9,"N/A") | J13: =COUNTIF('W09 - Siparişlerim Listesi'!H4:H9,"Beklemede")
A14: 10 | B14: W10 - Sipariş Detay & Takip | C14: W10 — Sipariş Detayı, Kargo Takibi, Yorum | D14: 7 | E14: =COUNTIF('W10 - Sipariş Detay & Takip'!H4:H10,"Geçti") | F14: =COUNTIF('W10 - Sipariş Detay & Takip'!H4:H10,"Kaldı") | G14: =COUNTIF('W10 - Sipariş Detay & Takip'!H4:H10,"Bloke") | H14: =COUNTIF('W10 - Sipariş Detay & Takip'!H4:H10,"Yapılamadı") | I14: =COUNTIF('W10 - Sipariş Detay & Takip'!H4:H10,"N/A") | J14: =COUNTIF('W10 - Sipariş Detay & Takip'!H4:H10,"Beklemede")
A15: 11 | B15: W11 - Sipariş İptal | C15: W11 — Sipariş İptal Akışı | D15: 6 | E15: =COUNTIF('W11 - Sipariş İptal'!H4:H9,"Geçti") | F15: =COUNTIF('W11 - Sipariş İptal'!H4:H9,"Kaldı") | G15: =COUNTIF('W11 - Sipariş İptal'!H4:H9,"Bloke") | H15: =COUNTIF('W11 - Sipariş İptal'!H4:H9,"Yapılamadı") | I15: =COUNTIF('W11 - Sipariş İptal'!H4:H9,"N/A") | J15: =COUNTIF('W11 - Sipariş İptal'!H4:H9,"Beklemede")
A16: 12 | B16: W12 - İade Talebi | C16: W12 — İade ve Değişim Akışı | D16: 10 | E16: =COUNTIF('W12 - İade Talebi'!H4:H13,"Geçti") | F16: =COUNTIF('W12 - İade Talebi'!H4:H13,"Kaldı") | G16: =COUNTIF('W12 - İade Talebi'!H4:H13,"Bloke") | H16: =COUNTIF('W12 - İade Talebi'!H4:H13,"Yapılamadı") | I16: =COUNTIF('W12 - İade Talebi'!H4:H13,"N/A") | J16: =COUNTIF('W12 - İade Talebi'!H4:H13,"Beklemede")
A17: 13 | B17: W13 - Profil & Ayarlar | C17: W13 — Profil, Adres, Şifre, Ödeme Yöntemleri | D17: 12 | E17: =COUNTIF('W13 - Profil & Ayarlar'!H4:H15,"Geçti") | F17: =COUNTIF('W13 - Profil & Ayarlar'!H4:H15,"Kaldı") | G17: =COUNTIF('W13 - Profil & Ayarlar'!H4:H15,"Bloke") | H17: =COUNTIF('W13 - Profil & Ayarlar'!H4:H15,"Yapılamadı") | I17: =COUNTIF('W13 - Profil & Ayarlar'!H4:H15,"N/A") | J17: =COUNTIF('W13 - Profil & Ayarlar'!H4:H15,"Beklemede")
A18: 14 | B18: W14 - Satıcı İlan Yönetimi | C18: W14 — Satıcı: İlan Oluşturma ve Yönetimi | D18: 9 | E18: =COUNTIF('W14 - Satıcı İlan Yönetimi'!H4:H12,"Geçti") | F18: =COUNTIF('W14 - Satıcı İlan Yönetimi'!H4:H12,"Kaldı") | G18: =COUNTIF('W14 - Satıcı İlan Yönetimi'!H4:H12,"Bloke") | H18: =COUNTIF('W14 - Satıcı İlan Yönetimi'!H4:H12,"Yapılamadı") | I18: =COUNTIF('W14 - Satıcı İlan Yönetimi'!H4:H12,"N/A") | J18: =COUNTIF('W14 - Satıcı İlan Yönetimi'!H4:H12,"Beklemede")
A19: 15 | B19: W15 - Satıcı Sipariş Yönetimi | C19: W15 — Satıcı: Sipariş İşleme ve Kargolama | D19: 8 | E19: =COUNTIF('W15 - Satıcı Sipariş Yönetimi'!H4:H11,"Geçti") | F19: =COUNTIF('W15 - Satıcı Sipariş Yönetimi'!H4:H11,"Kaldı") | G19: =COUNTIF('W15 - Satıcı Sipariş Yönetimi'!H4:H11,"Bloke") | H19: =COUNTIF('W15 - Satıcı Sipariş Yönetimi'!H4:H11,"Yapılamadı") | I19: =COUNTIF('W15 - Satıcı Sipariş Yönetimi'!H4:H11,"N/A") | J19: =COUNTIF('W15 - Satıcı Sipariş Yönetimi'!H4:H11,"Beklemede")
A20: 16 | B20: W16 - Teklifler | C20: W16 — Teklif (Offer) Akışı | D20: 9 | E20: =COUNTIF('W16 - Teklifler'!H4:H12,"Geçti") | F20: =COUNTIF('W16 - Teklifler'!H4:H12,"Kaldı") | G20: =COUNTIF('W16 - Teklifler'!H4:H12,"Bloke") | H20: =COUNTIF('W16 - Teklifler'!H4:H12,"Yapılamadı") | I20: =COUNTIF('W16 - Teklifler'!H4:H12,"N/A") | J20: =COUNTIF('W16 - Teklifler'!H4:H12,"Beklemede")
A21: 17 | B21: W17 - Takas Trade | C21: W17 — Takas (Trade) Akışı | D21: 8 | E21: =COUNTIF('W17 - Takas Trade'!H4:H11,"Geçti") | F21: =COUNTIF('W17 - Takas Trade'!H4:H11,"Kaldı") | G21: =COUNTIF('W17 - Takas Trade'!H4:H11,"Bloke") | H21: =COUNTIF('W17 - Takas Trade'!H4:H11,"Yapılamadı") | I21: =COUNTIF('W17 - Takas Trade'!H4:H11,"N/A") | J21: =COUNTIF('W17 - Takas Trade'!H4:H11,"Beklemede")
A22: 18 | B22: W18 - Mesajlar | C22: W18 — Mesajlaşma | D22: 9 | E22: =COUNTIF('W18 - Mesajlar'!H4:H12,"Geçti") | F22: =COUNTIF('W18 - Mesajlar'!H4:H12,"Kaldı") | G22: =COUNTIF('W18 - Mesajlar'!H4:H12,"Bloke") | H22: =COUNTIF('W18 - Mesajlar'!H4:H12,"Yapılamadı") | I22: =COUNTIF('W18 - Mesajlar'!H4:H12,"N/A") | J22: =COUNTIF('W18 - Mesajlar'!H4:H12,"Beklemede")
A23: 19 | B23: W19 - Bildirimler | C23: W19 — Bildirim Merkezi | D23: 6 | E23: =COUNTIF('W19 - Bildirimler'!H4:H9,"Geçti") | F23: =COUNTIF('W19 - Bildirimler'!H4:H9,"Kaldı") | G23: =COUNTIF('W19 - Bildirimler'!H4:H9,"Bloke") | H23: =COUNTIF('W19 - Bildirimler'!H4:H9,"Yapılamadı") | I23: =COUNTIF('W19 - Bildirimler'!H4:H9,"N/A") | J23: =COUNTIF('W19 - Bildirimler'!H4:H9,"Beklemede")
A24: 20 | B24: W20 - Favori Wishlist Koleksiyo | C24: W20 — Favoriler, Wishlist, Koleksiyonlar | D24: 8 | E24: =COUNTIF('W20 - Favori Wishlist Koleksiyo'!H4:H11,"Geçti") | F24: =COUNTIF('W20 - Favori Wishlist Koleksiyo'!H4:H11,"Kaldı") | G24: =COUNTIF('W20 - Favori Wishlist Koleksiyo'!H4:H11,"Bloke") | H24: =COUNTIF('W20 - Favori Wishlist Koleksiyo'!H4:H11,"Yapılamadı") | I24: =COUNTIF('W20 - Favori Wishlist Koleksiyo'!H4:H11,"N/A") | J24: =COUNTIF('W20 - Favori Wishlist Koleksiyo'!H4:H11,"Beklemede")
A25: 21 | B25: W21 - Üyelik Membership | C25: W21 — Üyelik Planları | D25: 8 | E25: =COUNTIF('W21 - Üyelik Membership'!H4:H11,"Geçti") | F25: =COUNTIF('W21 - Üyelik Membership'!H4:H11,"Kaldı") | G25: =COUNTIF('W21 - Üyelik Membership'!H4:H11,"Bloke") | H25: =COUNTIF('W21 - Üyelik Membership'!H4:H11,"Yapılamadı") | I25: =COUNTIF('W21 - Üyelik Membership'!H4:H11,"N/A") | J25: =COUNTIF('W21 - Üyelik Membership'!H4:H11,"Beklemede")
A26: 22 | B26: W22 - Statik & Yasal | C26: W22 — Statik ve Yasal Sayfalar | D26: 10 | E26: =COUNTIF('W22 - Statik & Yasal'!H4:H13,"Geçti") | F26: =COUNTIF('W22 - Statik & Yasal'!H4:H13,"Kaldı") | G26: =COUNTIF('W22 - Statik & Yasal'!H4:H13,"Bloke") | H26: =COUNTIF('W22 - Statik & Yasal'!H4:H13,"Yapılamadı") | I26: =COUNTIF('W22 - Statik & Yasal'!H4:H13,"N/A") | J26: =COUNTIF('W22 - Statik & Yasal'!H4:H13,"Beklemede")
A27: 23 | B27: W23 - Mobil & Responsive | C27: W23 — Mobil Görünüm ve Responsive | D27: 6 | E27: =COUNTIF('W23 - Mobil & Responsive'!H4:H9,"Geçti") | F27: =COUNTIF('W23 - Mobil & Responsive'!H4:H9,"Kaldı") | G27: =COUNTIF('W23 - Mobil & Responsive'!H4:H9,"Bloke") | H27: =COUNTIF('W23 - Mobil & Responsive'!H4:H9,"Yapılamadı") | I27: =COUNTIF('W23 - Mobil & Responsive'!H4:H9,"N/A") | J27: =COUNTIF('W23 - Mobil & Responsive'!H4:H9,"Beklemede")
A28: 24 | B28: A01 - Admin Login & Yetki | C28: A01 — Admin Girişi ve Yetkilendirme | D28: 7 | E28: =COUNTIF('A01 - Admin Login & Yetki'!H4:H10,"Geçti") | F28: =COUNTIF('A01 - Admin Login & Yetki'!H4:H10,"Kaldı") | G28: =COUNTIF('A01 - Admin Login & Yetki'!H4:H10,"Bloke") | H28: =COUNTIF('A01 - Admin Login & Yetki'!H4:H10,"Yapılamadı") | I28: =COUNTIF('A01 - Admin Login & Yetki'!H4:H10,"N/A") | J28: =COUNTIF('A01 - Admin Login & Yetki'!H4:H10,"Beklemede")
A29: 25 | B29: A02 - Dashboard & Analitik | C29: A02 — Dashboard, Analytics, Raporlar | D29: 5 | E29: =COUNTIF('A02 - Dashboard & Analitik'!H4:H8,"Geçti") | F29: =COUNTIF('A02 - Dashboard & Analitik'!H4:H8,"Kaldı") | G29: =COUNTIF('A02 - Dashboard & Analitik'!H4:H8,"Bloke") | H29: =COUNTIF('A02 - Dashboard & Analitik'!H4:H8,"Yapılamadı") | I29: =COUNTIF('A02 - Dashboard & Analitik'!H4:H8,"N/A") | J29: =COUNTIF('A02 - Dashboard & Analitik'!H4:H8,"Beklemede")
A30: 26 | B30: A03 - Ürün Yönetimi | C30: A03 — Ürün Listesi, Detay, Onay, Yorum | D30: 10 | E30: =COUNTIF('A03 - Ürün Yönetimi'!H4:H13,"Geçti") | F30: =COUNTIF('A03 - Ürün Yönetimi'!H4:H13,"Kaldı") | G30: =COUNTIF('A03 - Ürün Yönetimi'!H4:H13,"Bloke") | H30: =COUNTIF('A03 - Ürün Yönetimi'!H4:H13,"Yapılamadı") | I30: =COUNTIF('A03 - Ürün Yönetimi'!H4:H13,"N/A") | J30: =COUNTIF('A03 - Ürün Yönetimi'!H4:H13,"Beklemede")
A31: 27 | B31: A04 - Katalog Master | C31: A04 — Kategori, Marka, Attribute, Tag, Üretici, Model | D31: 8 | E31: =COUNTIF('A04 - Katalog Master'!H4:H11,"Geçti") | F31: =COUNTIF('A04 - Katalog Master'!H4:H11,"Kaldı") | G31: =COUNTIF('A04 - Katalog Master'!H4:H11,"Bloke") | H31: =COUNTIF('A04 - Katalog Master'!H4:H11,"Yapılamadı") | I31: =COUNTIF('A04 - Katalog Master'!H4:H11,"N/A") | J31: =COUNTIF('A04 - Katalog Master'!H4:H11,"Beklemede")
A32: 28 | B32: A05 - Sipariş Yönetimi | C32: A05 — Admin: Sipariş Listesi ve İşlemler | D32: 8 | E32: =COUNTIF('A05 - Sipariş Yönetimi'!H4:H11,"Geçti") | F32: =COUNTIF('A05 - Sipariş Yönetimi'!H4:H11,"Kaldı") | G32: =COUNTIF('A05 - Sipariş Yönetimi'!H4:H11,"Bloke") | H32: =COUNTIF('A05 - Sipariş Yönetimi'!H4:H11,"Yapılamadı") | I32: =COUNTIF('A05 - Sipariş Yönetimi'!H4:H11,"N/A") | J32: =COUNTIF('A05 - Sipariş Yönetimi'!H4:H11,"Beklemede")
A33: 29 | B33: A06 - Ödeme & İade & Payout | C33: A06 — Admin: Ödeme, İade, Payout Yönetimi | D33: 9 | E33: =COUNTIF('A06 - Ödeme & İade & Payout'!H4:H12,"Geçti") | F33: =COUNTIF('A06 - Ödeme & İade & Payout'!H4:H12,"Kaldı") | G33: =COUNTIF('A06 - Ödeme & İade & Payout'!H4:H12,"Bloke") | H33: =COUNTIF('A06 - Ödeme & İade & Payout'!H4:H12,"Yapılamadı") | I33: =COUNTIF('A06 - Ödeme & İade & Payout'!H4:H12,"N/A") | J33: =COUNTIF('A06 - Ödeme & İade & Payout'!H4:H12,"Beklemede")
A34: 30 | B34: A07 - Komisyon Vergi Kargo | C34: A07 — Komisyon, Vergi, Kargo Ayarları | D34: 5 | E34: =COUNTIF('A07 - Komisyon Vergi Kargo'!H4:H8,"Geçti") | F34: =COUNTIF('A07 - Komisyon Vergi Kargo'!H4:H8,"Kaldı") | G34: =COUNTIF('A07 - Komisyon Vergi Kargo'!H4:H8,"Bloke") | H34: =COUNTIF('A07 - Komisyon Vergi Kargo'!H4:H8,"Yapılamadı") | I34: =COUNTIF('A07 - Komisyon Vergi Kargo'!H4:H8,"N/A") | J34: =COUNTIF('A07 - Komisyon Vergi Kargo'!H4:H8,"Beklemede")
A35: 31 | B35: A08 - Kullanıcı Yönetimi | C35: A08 — Kullanıcı Listesi ve Detayı | D35: 7 | E35: =COUNTIF('A08 - Kullanıcı Yönetimi'!H4:H10,"Geçti") | F35: =COUNTIF('A08 - Kullanıcı Yönetimi'!H4:H10,"Kaldı") | G35: =COUNTIF('A08 - Kullanıcı Yönetimi'!H4:H10,"Bloke") | H35: =COUNTIF('A08 - Kullanıcı Yönetimi'!H4:H10,"Yapılamadı") | I35: =COUNTIF('A08 - Kullanıcı Yönetimi'!H4:H10,"N/A") | J35: =COUNTIF('A08 - Kullanıcı Yönetimi'!H4:H10,"Beklemede")
A36: 32 | B36: A09 - Satıcı Başvuru & Performa | C36: A09 — Satıcı Başvuruları ve Performans | D36: 6 | E36: =COUNTIF('A09 - Satıcı Başvuru & Performa'!H4:H9,"Geçti") | F36: =COUNTIF('A09 - Satıcı Başvuru & Performa'!H4:H9,"Kaldı") | G36: =COUNTIF('A09 - Satıcı Başvuru & Performa'!H4:H9,"Bloke") | H36: =COUNTIF('A09 - Satıcı Başvuru & Performa'!H4:H9,"Yapılamadı") | I36: =COUNTIF('A09 - Satıcı Başvuru & Performa'!H4:H9,"N/A") | J36: =COUNTIF('A09 - Satıcı Başvuru & Performa'!H4:H9,"Beklemede")
A37: 33 | B37: A10 - Üyelik Tier Yönetimi | C37: A10 — Membership Tier Yönetimi | D37: 4 | E37: =COUNTIF('A10 - Üyelik Tier Yönetimi'!H4:H7,"Geçti") | F37: =COUNTIF('A10 - Üyelik Tier Yönetimi'!H4:H7,"Kaldı") | G37: =COUNTIF('A10 - Üyelik Tier Yönetimi'!H4:H7,"Bloke") | H37: =COUNTIF('A10 - Üyelik Tier Yönetimi'!H4:H7,"Yapılamadı") | I37: =COUNTIF('A10 - Üyelik Tier Yönetimi'!H4:H7,"N/A") | J37: =COUNTIF('A10 - Üyelik Tier Yönetimi'!H4:H7,"Beklemede")
A38: 34 | B38: A11 - İndirim & Kupon | C38: A11 — Discount / Coupon Yönetimi | D38: 9 | E38: =COUNTIF('A11 - İndirim & Kupon'!H4:H12,"Geçti") | F38: =COUNTIF('A11 - İndirim & Kupon'!H4:H12,"Kaldı") | G38: =COUNTIF('A11 - İndirim & Kupon'!H4:H12,"Bloke") | H38: =COUNTIF('A11 - İndirim & Kupon'!H4:H12,"Yapılamadı") | I38: =COUNTIF('A11 - İndirim & Kupon'!H4:H12,"N/A") | J38: =COUNTIF('A11 - İndirim & Kupon'!H4:H12,"Beklemede")
A39: 35 | B39: A12 - Email Şablonları | C39: A12 — E-posta Şablon Yönetimi | D39: 5 | E39: =COUNTIF('A12 - Email Şablonları'!H4:H8,"Geçti") | F39: =COUNTIF('A12 - Email Şablonları'!H4:H8,"Kaldı") | G39: =COUNTIF('A12 - Email Şablonları'!H4:H8,"Bloke") | H39: =COUNTIF('A12 - Email Şablonları'!H4:H8,"Yapılamadı") | I39: =COUNTIF('A12 - Email Şablonları'!H4:H8,"N/A") | J39: =COUNTIF('A12 - Email Şablonları'!H4:H8,"Beklemede")
A40: 36 | B40: A13 - Yorum & Moderasyon | C40: A13 — Yorum ve Moderasyon Kuyruğu | D40: 5 | E40: =COUNTIF('A13 - Yorum & Moderasyon'!H4:H8,"Geçti") | F40: =COUNTIF('A13 - Yorum & Moderasyon'!H4:H8,"Kaldı") | G40: =COUNTIF('A13 - Yorum & Moderasyon'!H4:H8,"Bloke") | H40: =COUNTIF('A13 - Yorum & Moderasyon'!H4:H8,"Yapılamadı") | I40: =COUNTIF('A13 - Yorum & Moderasyon'!H4:H8,"N/A") | J40: =COUNTIF('A13 - Yorum & Moderasyon'!H4:H8,"Beklemede")
A41: 37 | B41: A14 - Reklamlar | C41: A14 — Reklam ve Sponsorlu İçerik | D41: 4 | E41: =COUNTIF('A14 - Reklamlar'!H4:H7,"Geçti") | F41: =COUNTIF('A14 - Reklamlar'!H4:H7,"Kaldı") | G41: =COUNTIF('A14 - Reklamlar'!H4:H7,"Bloke") | H41: =COUNTIF('A14 - Reklamlar'!H4:H7,"Yapılamadı") | I41: =COUNTIF('A14 - Reklamlar'!H4:H7,"N/A") | J41: =COUNTIF('A14 - Reklamlar'!H4:H7,"Beklemede")
A42: 38 | B42: A15 - Takas Yönetimi | C42: A15 — Admin: Takas (Trade) Yönetimi | D42: 6 | E42: =COUNTIF('A15 - Takas Yönetimi'!H4:H9,"Geçti") | F42: =COUNTIF('A15 - Takas Yönetimi'!H4:H9,"Kaldı") | G42: =COUNTIF('A15 - Takas Yönetimi'!H4:H9,"Bloke") | H42: =COUNTIF('A15 - Takas Yönetimi'!H4:H9,"Yapılamadı") | I42: =COUNTIF('A15 - Takas Yönetimi'!H4:H9,"N/A") | J42: =COUNTIF('A15 - Takas Yönetimi'!H4:H9,"Beklemede")
...

Sheet 02 - Yönergeler
A1: TEST PLANI KULLANIM YÖNERGELERİ
B4: Belge Yapısı
B5: 00 - Kapak | C5: Proje bilgileri, doküman versiyonu ve resmi imza alanı.
B6: 01 - Özet | C6: Tüm sheet'lerin sonuç dağılımı (otomatik formüllerle güncellenir).
B7: 02 - Yönergeler | C7: Bu sayfa: kullanım, kolon açıklamaları, durum kodları.
B8: W## - Web | C8: Web platformu test sayfaları (kullanıcı tarafı).
B9: A## - Admin | C9: Admin paneli test sayfaları.
B10: E## - E2E | C10: Uçtan uca (end-to-end) iş akışı senaryoları.
B11: C## - Cross | C11: Mail bildirimleri, otomatik işler, edge case, güvenlik gibi yatay konular.
B12: ZZ - İmza | C12: Tüm sheet sonuçlarının özet imza ve kabul beyanı sayfası.
B14: Sütun Açıklamaları
B15: Test ID | C15: Sheet bazlı tekil tanımlayıcı (örn. W01-005).
B16: Modül / Sayfa | C16: Senaryonun ait olduğu sayfa veya iş alanı.
B17: Senaryo / Test Adı | C17: Yapılacak testin başlığı (kısa).
B18: Önkoşullar | C18: Test başlamadan önce sağlanması gereken durum.
B19: Adımlar | C19: Test eden tarafından sırayla uygulanacak adımlar.
B20: Beklenen Sonuç | C20: Adımlar tamamlandığında olması gereken davranış.
B21: Gerçek Sonuç | C21: Test eden gözlemini buraya yazar.
B22: Durum | C22: Beklemede / Geçti / Kaldı / Bloke / Yapılamadı / N/A — dropdown.
B23: Test Eden | C23: Senaryoyu yürüten kişinin adı.
B24: Test Tarihi | C24: Senaryonun çalıştırıldığı tarih (gg.aa.yyyy).
B25: Tarayıcı / Cihaz | C25: Hangi tarayıcı veya cihazla test edildi — dropdown.
B26: Öncelik | C26: Kritik / Yüksek / Orta / Düşük — senaryo önemi.
B27: Notlar / Hata Linki | C27: Bug tracker linki, ekran görüntüsü adı, ek not.
B29: Durum Kodları
B30: Beklemede | C30: Henüz test edilmedi (varsayılan).
B31: Geçti | C31: Beklenen sonuç eksiksiz gözlemlendi.
B32: Kaldı | C32: Beklenen sonuç gözlemlenmedi → bug. Notlar alanına detay/link eklenmeli.
B33: Bloke | C33: Başka bir hata veya eksik nedeniyle test başlatılamadı/sürdürülemedi.
B34: Yapılamadı | C34: Test ortamında ilgili özellik henüz hazır değil.
B35: N/A | C35: Bu projede uygulanmıyor (örn. opsiyonel feature kapsam dışı).
B37: Test Süreci
B38: 1. | C38: Tarodan ekibi tüm senaryoları yürütür ve sonuçları işaretler.
B39: 2. | C39: Müşteri kendi ortamında aynı senaryoları yürütür ve doğrular.
B40: 3. | C40: Bug bulunursa 'Notlar' kolonuna issue linki/açıklaması yazılır.
B41: 4. | C41: Tüm 'Kaldı' senaryolar için düzeltme yapılıp yeniden test edilir.
B42: 5. | C42: Sheet sonundaki imza alanları her iki taraf tarafından imzalanır.
B43: 6. | C43: Kapak ve 'ZZ - İmza' sayfaları nihai onay olarak imzalanır.

Sheet W01 - Auth Kayıt-Giriş
A1: W01 — Kayıt, Giriş ve Çıkış
A2: Bireysel kayıt, kurumsal kayıt, giriş, çıkış ve form doğrulamaları.
A3: Test ID | B3: Modül / Sayfa | C3: Senaryo / Test Adı | D3: Önkoşullar | E3: Adımlar (numaralı) | F3: Beklenen Sonuç | G3: Gerçek Sonuç | H3: Durum | I3: Test Eden | J3: Test Tarihi | K3: Tarayıcı / Cihaz | L3: Öncelik | M3: Notlar / Hata Linki
A4: W01-001 | B4: W01 | C4: Yeni bireysel kullanıcı kaydı (geçerli bilgilerle) | D4: Hiç kayıt olmamış e-posta hazır. | E4: 1. /register sayfasına git 2. Ad, soyad, e-posta, telefon, doğum tarihi, şifre gir 3. KVKK ve sözleşme onayını işaretle 4. Kayıt Ol'a bas | F4: Hesap oluşturulur, e-posta doğrulama maili tetiklenir, kullanıcı yönlendirilir. | H4: Beklemede | L4: Kritik
A5: W01-002 | B5: W01 | C5: Aynı e-posta ile ikinci kez kayıt | D5: Daha önce kayıtlı bir e-posta var. | E5: 1. /register sayfasına git 2. Mevcut e-postayı gir, formu doldur 3. Kayıt Ol'a bas | F5: “Bu e-posta zaten kullanılıyor” hatası, giriş sayfasına link gösterilir. | H5: Beklemede | L5: Yüksek
A6: W01-003 | B6: W01 | C6: Şifre güvenlik kuralı (zayıf şifre reddi) | D6: — | E6: 1. Kayıt formunu doldur, şifreye '123456' gir 2. Kayıt Ol'a bas | F6: Şifre yetersiz hatası; kabul edilmiyor. | H6: Beklemede | L6: Yüksek
A7: W01-004 | B7: W01 | C7: Telefon numarası formatı doğrulama | D7: — | E7: 1. Telefonu '12345' olarak gir, formu gönder | F7: Geçersiz telefon hatası; submit engellenir. | H7: Beklemede | L7: Orta
A8: W01-005 | B8: W01 | C8: KVKK onayı işaretlenmeden kayıt denenmesi | D8: — | E8: 1. Tüm alanları doldur, KVKK onayını işaretleme 2. Kayıt Ol'a bas | F8: Form gönderilemez; KVKK uyarısı gösterilir. | H8: Beklemede | L8: Yüksek
A9: W01-006 | B9: W01 | C9: Kurumsal (business) hesap kaydı | D9: — | E9: 1. /register/business sayfasına git 2. Şirket adı, vergi numarası, KVKK onayı, kişisel bilgiler gir 3. Kayıt Ol'a bas | F9: Kurumsal hesap oluşturulur, satıcı uygunluk başvurusu kuyruğa alınır. | H9: Beklemede | L9: Yüksek
A10: W01-007 | B10: W01 | C10: Vergi numarası geçersiz format | D10: — | E10: 1. Kurumsal kayıtta vergi numarasına 'abc' gir 2. Submit | F10: Vergi numarası format hatası gösterilir. | H10: Beklemede | L10: Orta
A11: W01-008 | B11: W01 | C11: Geçerli bilgilerle giriş | D11: Doğrulanmış kullanıcı. | E11: 1. /login sayfasına git 2. E-posta + şifre gir 3. Giriş Yap'a bas | F11: Anasayfa veya yönlendirme hedefine giriş yapılmış olarak ulaşılır; üst menüde profil görünür. | H11: Beklemede | L11: Kritik
A12: W01-009 | B12: W01 | C12: Yanlış şifre ile giriş | D12: Mevcut hesap. | E12: 1. E-postayı doğru, şifreyi yanlış gir 2. Giriş Yap'a bas | F12: Hata mesajı; sayfa giriş sayfasında kalır; sayaç artar. | H12: Beklemede | L12: Yüksek
A13: W01-010 | B13: W01 | C13: 5 başarısız denemeden sonra hesap kilidi | D13: Aynı kullanıcıya 5 yanlış şifre denemesi yapıldı. | E13: 1. 6. denemeyi yap | F13: Hesap geçici kilitlenir (30 dk) veya rate-limit uyarısı verilir. | H13: Beklemede | L13: Yüksek
A14: W01-011 | B14: W01 | C14: Çıkış (logout) | D14: Giriş yapılmış oturum. | E14: 1. Profil menüsünden 'Çıkış'a bas | F14: Oturum sonlandırılır, anasayfaya yönlendirilir, korumalı sayfalara erişim engellenir. | H14: Beklemede | L14: Yüksek
A15: W01-012 | B15: W01 | C15: Korumalı sayfaya misafir erişimi | D15: Çıkış yapılmış. | E15: 1. /orders veya /profile adresine git | F15: /login?redirect=... adresine yönlendirme yapılır; giriş sonrası asıl sayfaya döner. | H15: Beklemede | L15: Kritik
A16: W01-013 | B16: W01 | C16: Beni Hatırla seçeneği | D16: — | E16: 1. Beni Hatırla işaretli giriş yap 2. Tarayıcıyı kapatıp yeniden aç | F16: Oturum hala açıktır. | H16: Beklemede | L16: Orta
A19: Bu sayfadaki tüm senaryolar test edilmiş ve sonuçlar yukarıda işaretlenmiştir.
A20: Test Eden (Tarodan) | D20: Tarih | G20: Onaylayan (Müşteri) | J20: Tarih

Sheet W02 - Şifre & Email Doğrulama
A1: W02 — Şifre Sıfırlama, E-posta ve OTP Doğrulama
A2: Şifre unuttum akışı, e-posta doğrulama, misafir e-posta OTP, rate-limit.
A3: Test ID | B3: Modül / Sayfa | C3: Senaryo / Test Adı | D3: Önkoşullar | E3: Adımlar (numaralı) | F3: Beklenen Sonuç | G3: Gerçek Sonuç | H3: Durum | I3: Test Eden | J3: Test Tarihi | K3: Tarayıcı / Cihaz | L3: Öncelik | M3: Notlar / Hata Linki
A4: W02-001 | B4: W02 | C4: Şifremi Unuttum maili gönderme | D4: Kayıtlı e-posta. | E4: 1. /forgot-password sayfasına git 2. E-postayı gir, Gönder'e bas | F4: “Mail gönderildi” bilgisi; e-postaya 1 saat geçerli sıfırlama linki düşer. | H4: Beklemede | L4: Kritik
A5: W02-002 | B5: W02 | C5: Şifre sıfırlama linkine tıklama (geçerli token) | D5: Yeni gönderilmiş sıfırlama maili. | E5: 1. Maildeki linke tıkla 2. /reset-password açılır 3. Yeni şifre + tekrar gir, Gönder | F5: Şifre güncellenir; giriş sayfasına yönlendirir; yeni şifre ile giriş çalışır. | H5: Beklemede | L5: Kritik
A6: W02-003 | B6: W02 | C6: Süresi dolmuş token ile sıfırlama | D6: 1 saatten eski token. | E6: 1. Eski token'lı linke tıkla | F6: “Link süresi dolmuş” mesajı; yeniden gönder seçeneği sunulur. | H6: Beklemede | L6: Yüksek
A7: W02-004 | B7: W02 | C7: Aynı token ile ikinci kez sıfırlama | D7: Daha önce kullanılmış token. | E7: 1. Aynı linke ikinci kez tıkla | F7: Token tek kullanımlık; geçersiz token mesajı. | H7: Beklemede | L7: Yüksek
A8: W02-005 | B8: W02 | C8: Kayıtsız e-posta ile şifre sıfırlama isteği | D8: — | E8: 1. Sistemde olmayan bir e-posta gir, Gönder | F8: Kullanıcı yanıltma için aynı genel mesaj gösterilir; mail gönderilmez (enumeration koruması). | H8: Beklemede | L8: Yüksek
A9: W02-006 | B9: W02 | C9: Yeni kullanıcı e-posta doğrulama maili | D9: Yeni kayıtlı, doğrulanmamış kullanıcı. | E9: 1. Maildeki doğrulama linkine tıkla | F9: E-posta doğrulanır, profilde 'doğrulandı' rozeti görünür. | H9: Beklemede | L9: Kritik
A10: W02-007 | B10: W02 | C10: Doğrulanmamış kullanıcı satışa çıkmaya çalışır | D10: E-posta doğrulanmamış. | E10: 1. /listings/new veya /sell sayfasına git | F10: “Önce e-postanızı doğrulayın” uyarısı; doğrulama maili tekrar gönder linki. | H10: Beklemede | L10: Yüksek
A11: W02-008 | B11: W02 | C11: Misafir checkout — e-posta OTP gönder | D11: Misafir checkout adımına gelinmiş. | E11: 1. E-postayı gir 2. 'Kod Gönder' butonuna bas | F11: “Kod gönderildi” bilgisi; e-postaya 6 haneli kod düşer (TTL ~10dk). | H11: Beklemede | L11: Kritik
A12: W02-009 | B12: W02 | C12: Misafir OTP — geçerli kod ile doğrulama | D12: OTP gönderilmiş. | E12: 1. 6 haneli doğru kodu gir 2. Doğrula | F12: Doğrulama başarılı; ödeme adımına geçilir. | H12: Beklemede | L12: Kritik
A13: W02-010 | B13: W02 | C13: Misafir OTP — yanlış kod denemesi | D13: OTP gönderilmiş. | E13: 1. Yanlış kod gir, Doğrula | F13: Hata mesajı; deneme hakkı azalır. | H13: Beklemede | L13: Orta
A14: W02-011 | B14: W02 | C14: Misafir OTP — 5 yanlış denemeden sonra rate-limit | D14: 5 yanlış deneme yapıldı. | E14: 1. 6. denemeyi yap | F14: “Çok fazla deneme, lütfen sonra tekrar deneyin” mesajı; 1 saat blok. | H14: Beklemede | L14: Yüksek
A15: W02-012 | B15: W02 | C15: OTP yeniden gönder cooldown | D15: Az önce kod gönderildi. | E15: 1. Hemen yeniden 'Kod Gönder'e bas | F15: 60 sn cooldown; sayaç görünür. | H15: Beklemede | L15: Orta
A16: W02-013 | B16: W02 | C16: Süresi dolmuş OTP | D16: 10+ dakika beklenmiş. | E16: 1. Eski kodu gir | F16: “Kodun süresi doldu, yeniden talep edin.” | H16: Beklemede | L16: Orta
A19: Bu sayfadaki tüm senaryolar test edilmiş ve sonuçlar yukarıda işaretlenmiştir.
A20: Test Eden (Tarodan) | D20: Tarih | G20: Onaylayan (Müşteri) | J20: Tarih

Sheet W03 - Anasayfa & Keşif
A1: W03 — Anasayfa, Listeleme, Arama, Kategori, Marka, Üretici
A2: Misafir/üye gezinme, filtreleme, sıralama, sonuç listeleri.
A3: Test ID | B3: Modül / Sayfa | C3: Senaryo / Test Adı | D3: Önkoşullar | E3: Adımlar (numaralı) | F3: Beklenen Sonuç | G3: Gerçek Sonuç | H3: Durum | I3: Test Eden | J3: Test Tarihi | K3: Tarayıcı / Cihaz | L3: Öncelik | M3: Notlar / Hata Linki
A4: W03-001 | B4: W03 | C4: Anasayfa açılışı | D4: — | E4: 1. / adresine git | F4: Hero, marka carousel, indirimli ürünler, popüler ilanlar, koleksiyonlar yüklenir; kırılma yok. | H4: Beklemede | L4: Kritik
A5: W03-002 | B5: W03 | C5: Genel arama (üst bar) | D5: — | E5: 1. Üst arama kutusuna anahtar kelime gir, Enter | F5: /search sayfası açılır, sonuçlar relevansa göre listelenir. | H5: Beklemede | L5: Orta
A6: W03-003 | B6: W03 | C6: Boş sonuçlu arama | D6: — | E6: 1. Var olmayan bir kelime ara | F6: “Sonuç bulunamadı” boş durum kartı; öneriler gösterilir. | H6: Beklemede | L6: Orta
A7: W03-004 | B7: W03 | C7: Kategori sayfasını açma | D7: Aktif bir kategori var. | E7: 1. /category/[slug] aç | F7: Kategori başlığı, ürünler ve filtre paneli görünür. | H7: Beklemede | L7: Orta
A8: W03-005 | B8: W03 | C8: Filtre uygulama (marka, fiyat, durum) | D8: Kategori sayfasında. | E8: 1. Filtreden marka seç 2. Min-max fiyat gir 3. Durum seç | F8: Liste gerçek zamanlı güncellenir; URL'ye filtre query'si eklenir. | H8: Beklemede | L8: Orta
A9: W03-006 | B9: W03 | C9: Filtreleri temizle | D9: Birkaç filtre aktif. | E9: 1. 'Filtreleri Temizle'ye bas | F9: Tüm filtreler kalkar, tüm liste döner. | H9: Beklemede | L9: Orta
A10: W03-007 | B10: W03 | C10: Sıralama (yeni, popüler, fiyat artan/azalan) | D10: Liste sayfası açık. | E10: 1. Sıralama dropdown'undan farklı seçenekleri dene | F10: Liste her seçimde doğru sıralanır. | H10: Beklemede | L10: Orta
A11: W03-008 | B11: W03 | C11: Grid / liste görünüm değiştirme | D11: — | E11: 1. Grid → Liste, Liste → Grid butonlarına bas | F11: Görünüm değişir, kullanıcı tercihi sayfa yenilense bile (mümkünse) korunur. | H11: Beklemede | L11: Orta
A12: W03-009 | B12: W03 | C12: Sayfalama (pagination) | D12: Çok ürünlü kategori. | E12: 1. Alttan ileri/geri sayfa butonlarını kullan | F12: Sayfa numarası ve URL güncellenir; ürünler değişir; scroll üste döner. | H12: Beklemede | L12: Orta
A13: W03-010 | B13: W03 | C13: Marka detay sayfası | D13: — | E13: 1. /brands listesinden bir markaya tıkla | F13: /brands/[slug] açılır; markanın ürünleri görünür. | H13: Beklemede | L13: Orta
A14: W03-011 | B14: W03 | C14: Üretici detay sayfası (TR slug) | D14: — | E14: 1. /ureticiler aç, bir üreticiye tıkla | F14: /ureticiler/[slug] açılır. | H14: Beklemede | L14: Orta
A15: W03-012 | B15: W03 | C15: Model detay sayfası | D15: — | E15: 1. /models aç, bir modele tıkla | F15: /models/[slug] açılır. | H15: Beklemede | L15: Orta
... A17: W03-014 | B17: W03 | C17: Son aramalar | D17: Birkaç kez arama yapılmış. | E17: 1. Arama kutusuna odaklan | F17: Son arama önerileri dropdown'da listelenir. | H17: Beklemede | L17: Orta
A20: Bu sayfadaki tüm senaryolar test edilmiş ve sonuçlar yukarıda işaretlenmiştir.
A21: Test Eden (Tarodan) | D21: Tarih | G21: Onaylayan (Müşteri) | J21: Tarih

Sheet W04 - Ürün Detay
A1: W04 — Ürün Detay Sayfası
A2: Ürün galerisi, satıcı bilgisi, sepete ekleme, teklif, mesaj, favori.
A3: Test ID | B3: Modül / Sayfa | C3: Senaryo / Test Adı | D3: Önkoşullar | E3: Adımlar (numaralı) | F3: Beklenen Sonuç | G3: Gerçek Sonuç | H3: Durum | I3: Test Eden | J3: Test Tarihi | K3: Tarayıcı / Cihaz | L3: Öncelik | M3: Notlar / Hata Linki
A4: W04-001 | B4: W04 | C4: Ürün detayı yükleme | D4: Aktif bir ürün ID'si. | E4: 1. /listings/[id] aç | F4: Tüm görseller, başlık, fiyat, satıcı kartı, açıklama eksiksiz yüklenir. | H4: Beklemede | L4: Kritik
A5: W04-002 | B5: W04 | C5: Görsel galeri ve zoom | D5: Çoklu görselli ürün. | E5: 1. Küçük görsellere tıkla, ana görsel değişir 2. Görselin üzerine gel — zoom çalışır | F5: Galeri sorunsuz çalışır; mobilde swipe destekler. | H5: Beklemede | L5: Orta
A6: W04-003 | B6: W04 | C6: Sepete ekle (üye) | D6: Giriş yapmış kullanıcı. | E6: 1. Sepete Ekle butonuna bas | F6: Sepet sayacı 1 artar; toast bildirim görünür. | H6: Beklemede | L6: Kritik
A7: W04-004 | B7: W04 | C7: Sepete ekle (misafir) | D7: Çıkış yapılmış oturum. | E7: 1. Sepete Ekle | F7: Misafir sepetine eklenir (localStorage); sayaç güncellenir. | H7: Beklemede | L7: Orta
A8: W04-005 | B8: W04 | C8: Stok tükenmiş ürün | D8: Quantity = 0. | E8: 1. Ürün detayını aç | F8: “Satıldı” rozeti görünür; sepete ekle disabled; teklif/mesaj hala mümkün. | H8: Beklemede | L8: Orta
A9: W04-006 | B9: W04 | C9: Kendi ürününü görüntüleme | D9: Satıcı, kendi ilanına bakıyor. | E9: 1. Kendi ilanını aç | F9: Sepete Ekle/Teklif yerine 'Düzenle' / 'İlanı Kapat' butonları görünür. | H9: Beklemede | L9: Orta
A10: W04-007 | B10: W04 | C10: Favorilere ekle/çıkar | D10: Üye giriş. | E10: 1. Kalp ikonuna bas 2. Tekrar bas | F10: Eklenir, çıkarılır; sayaç ve favori sayfası güncellenir. | H10: Beklemede | L10: Orta
A11: W04-008 | B11: W04 | C11: Teklif Ver modalı (üye) | D11: Üye, başkasının ürünü. | E11: 1. 'Teklif Ver' butonuna bas 2. Modal'da fiyat gir 3. Gönder | F11: Min %50 vb. validasyonlar geçilir, teklif gönderilir, satıcıya bildirim/mail tetiklenir. | H11: Beklemede | L11: Kritik
A12: W04-009 | B12: W04 | C12: Çok düşük teklif | D12: — | E12: 1. Ürün fiyatının %10'unu teklif et | F12: “Minimum teklif” uyarısı; gönderilmez. | H12: Beklemede | L12: Orta
A13: W04-010 | B13: W04 | C13: Satıcıya mesaj gönder | D13: Üye giriş, başka satıcının ürünü. | E13: 1. 'Mesaj Gönder' butonuna bas, mesajı yaz, gönder | F13: Mesaj başarıyla gönderilir; /messages sayfasında thread oluşur. | H13: Beklemede | L13: Orta
A14: W04-011 | B14: W04 | C14: Mesajda telefon/IBAN içerik filtresi | D14: — | E14: 1. Mesaj kutusuna telefon numarası yaz, gönder | F14: Filtre tetiklenir; mesaj engellenir veya maskelenir; uyarı gösterilir. | H14: Beklemede | L14: Yüksek
A15: W04-012 | B15: W04 | C15: Takas başlat | D15: Üye, takasa açık ürün. | E15: 1. 'Takas Öner' butonuna bas, kendi ürününü seç, gönder | F15: Trade taslağı oluşur, /trades altında listelenir. | H15: Beklemede | L15: Orta
... A17: W04-014 | B17: W04 | C17: Yorumlar tabı | D17: Yorumu olan ürün. | E17: 1. Yorumlar bölümüne in | F17: Yorumlar listelenir; sıralama (yeni/eski/yıldız) çalışır. | H17: Beklemede | L17: Orta
A20: Bu sayfadaki tüm senaryolar test edilmiş ve sonuçlar yukarıda işaretlenmiştir.
A21: Test Eden (Tarodan) | D21: Tarih | G21: Onaylayan (Müşteri) | J21: Tarih

Sheet W05 - Sepet
A1: W05 — Sepet İşlemleri
A2: Ekleme, miktar değişimi, kupon, kargo, boş sepet, oturum birleştirme.
A3: Test ID | B3: Modül / Sayfa | C3: Senaryo / Test Adı | D3: Önkoşullar | E3: Adımlar (numaralı) | F3: Beklenen Sonuç | G3: Gerçek Sonuç | H3: Durum | I3: Test Eden | J3: Test Tarihi | K3: Tarayıcı / Cihaz | L3: Öncelik | M3: Notlar / Hata Linki
A4: W05-001 | B4: W05 | C4: Sepet yükleme (üye) | D4: Üye, sepete önceden eklenmiş ürünler. | E4: 1. /cart sayfasını aç | F4: Tüm ürünler, satıcı, fiyat ve özet panel doğru görünür. | H4: Beklemede | L4: Kritik
A5: W05-002 | B5: W05 | C5: Boş sepet ekranı | D5: Hiç ürün eklenmemiş. | E5: 1. /cart aç | F5: “Sepetiniz boş” mesajı + 'Alışverişe Devam Et' butonu. | H5: Beklemede | L5: Orta
A6: W05-003 | B6: W05 | C6: Ürün miktarı artırma/azaltma | D6: Sepette ürün var. | E6: 1. + ve - butonlarıyla miktarı değiştir | F6: Toplam ve KDV anlık güncellenir; stok limitini aşmaya izin vermez. | H6: Beklemede | L6: Orta
A7: W05-004 | B7: W05 | C7: Sepetten ürün çıkarma | D7: — | E7: 1. Çöp kutusu/Kaldır butonuna bas | F7: Ürün kalkar; toplam yeniden hesaplanır; toast onay. | H7: Beklemede | L7: Orta
A8: W05-005 | B8: W05 | C8: Kupon kodu uygulama (geçerli) | D8: Aktif bir kupon kodu. | E8: 1. Kupon alanına kodu gir, Uygula | F8: İndirim satırı eklenir; toplam azalır; kupon kuralları geçerli. | H8: Beklemede | L8: Orta
A9: W05-006 | B9: W05 | C9: Geçersiz kupon | D9: — | E9: 1. Olmayan bir kod gir, Uygula | F9: Hata mesajı; toplam değişmez. | H9: Beklemede | L9: Orta
A10: W05-007 | B10: W05 | C10: Kargo eşiği (örn. 500 TL üstü ücretsiz) | D10: Yapılandırma değeri biliniyor. | E10: 1. Tutarı eşiğin altında ve üstünde dene | F10: Eşik altında kargo ücreti, üstünde 'Ücretsiz' görünür. | H10: Beklemede | L10: Orta
A11: W05-008 | B11: W05 | C11: Misafir → giriş yapınca sepet birleşmesi | D11: Misafir olarak ürün eklenmiş. | E11: 1. Giriş yap | F11: Misafir sepeti üye sepetiyle birleşir; çift kayıt oluşmaz. | H11: Beklemede | L11: Orta
A12: W05-009 | B12: W05 | C12: Stok düşmüş ürün uyarısı | D12: Sepetteki üründen başkası satın aldı. | E12: 1. Sepeti yenile | F12: “Stok azaldı/satıldı” uyarısı; checkout'a geçişe izin verilmez. | H12: Beklemede | L12: Orta
A13: W05-010 | B13: W05 | C13: Devam Et — Checkout'a yönlendir | D13: Sepette ürün var. | E13: 1. 'Ödemeye Geç' butonuna bas | F13: /checkout sayfasına geçilir; üye için adres adımı, misafir için e-posta adımı. | H13: Beklemede | L13: Orta
A16: Bu sayfadaki tüm senaryolar test edilmiş ve sonuçlar yukarıda işaretlenmiştir.
A17: Test Eden (Tarodan) | D17: Tarih | G17: Onaylayan (Müşteri) | J17: Tarih

Sheet W06 - Misafir Checkout
A1: W06 — Misafir Checkout Akışı (E-posta OTP)
A2: Misafir kullanıcının kayıt olmadan satın alma süreci.
A3: Test ID | B3: Modül / Sayfa | C3: Senaryo / Test Adı | D3: Önkoşullar | E3: Adımlar (numaralı) | F3: Beklenen Sonuç | G3: Gerçek Sonuç | H3: Durum | I3: Test Eden | J3: Test Tarihi | K3: Tarayıcı / Cihaz | L3: Öncelik | M3: Notlar / Hata Linki
A4: W06-001 | B4: W06 | C4: Misafir e-posta + OTP doğrulama | D4: Sepet dolu, çıkış yapılmış. | E4: 1. /checkout aç 2. E-posta gir, Kod Gönder 3. Maildeki kodu gir, Doğrula | F4: Doğrulama OK; adres adımına geçer. | H4: Beklemede | L4: Kritik
A5: W06-002 | B5: W06 | C5: Yeni teslimat adresi girme | D5: OTP doğrulandı. | E5: 1. Ad, telefon, il, ilçe, adres, posta kodu gir 2. Devam et | F5: Adres validasyonları geçer; ödeme adımına geçilir. | H5: Beklemede | L5: Orta
A6: W06-003 | B6: W06 | C6: Faturalandırma adresi farklı seçeneği | D6: Adres adımında. | E6: 1. 'Faturalandırma adresi farklı' işaretle 2. Yeni fatura adresi gir | F6: İki ayrı adres kaydedilir; sipariş özetinde görünür. | H6: Beklemede | L6: Orta
A7: W06-004 | B7: W06 | C7: Kurumsal fatura talebi | D7: — | E7: 1. Kurumsal fatura işaretle, vergi dairesi/no gir | F7: Kurumsal fatura bilgileri kaydedilir. | H7: Beklemede | L7: Orta
A8: W06-005 | B8: W06 | C8: Sipariş özeti doğrulama | D8: Adres + ödeme seçildi. | E8: 1. Özet ekranını incele | F8: Ürünler, kargo, vergi, kupon, toplam doğru gösterilir. | H8: Beklemede | L8: Orta
A9: W06-006 | B9: W06 | C9: Mesafeli satış sözleşmesi onayı | D9: Özet ekranda. | E9: 1. Onay kutusunu işaretle, Siparişi Onayla'ya bas | F9: Onaysız ödeme başlatılamaz; onay sonrası PayTR iframe'ine geçer. | H9: Beklemede | L9: Yüksek
A10: W06-007 | B10: W06 | C10: Misafir sipariş takip linki | D10: Misafir siparişi tamamlandı. | E10: 1. Mailde gelen takip linkine tıkla 2. /track-order sayfası | F10: E-posta + sipariş no ile sipariş detayına erişilir. | H10: Beklemede | L10: Orta
A11: W06-008 | B11: W06 | C11: Misafir sipariş için iade talebi | D11: Teslim edilmiş misafir siparişi. | E11: 1. /track-order üzerinden detaya git 2. İade Talebi başlat | F11: İade talebi oluşur; e-postayla durum güncellemeleri gelir. | H11: Beklemede | L11: Orta
A14: Bu sayfadaki tüm senaryolar test edilmiş ve sonuçlar yukarıda işaretlenmiştir.
A15: Test Eden (Tarodan) | D15: Tarih | G15: Onaylayan (Müşteri) | J15: Tarih

Sheet W07 - Üye Checkout
A1: W07 — Üye Checkout Akışı
A2: Kayıtlı kullanıcı için adres seçimi, ödeme, sipariş onayı.
A3: Test ID | B3: Modül / Sayfa | C3: Senaryo / Test Adı | D3: Önkoşullar | E3: Adımlar (numaralı) | F3: Beklenen Sonuç | G3: Gerçek Sonuç | H3: Durum | I3: Test Eden | J3: Test Tarihi | K3: Tarayıcı / Cihaz | L3: Öncelik | M3: Notlar / Hata Linki
A4: W07-001 | B4: W07 | C4: Kayıtlı adres seçimi | D4: Üye, kayıtlı adres var. | E4: 1. /checkout aç 2. Adresler listesinden seç 3. Devam et | F4: Adres seçilir; ödeme adımına geçer. | H4: Beklemede | L4: Kritik
A5: W07-002 | B5: W07 | C5: Adres yokken yeni adres ekle | D5: Hiç adres yok. | E5: 1. Yeni Adres formunu doldur, kaydet | F5: Adres profil hesabına da kaydedilir; checkout devam eder. | H5: Beklemede | L5: Orta
A6: W07-003 | B6: W07 | C6: Varsayılan adres seçimi | D6: Çok adres var. | E6: 1. Bir adresi 'Varsayılan' yap | F6: Sonraki checkout'larda otomatik seçili gelir. | H6: Beklemede | L6: Orta
A7: W07-004 | B7: W07 | C7: Kayıtlı kart kullanma (varsa) | D7: Daha önce kart kaydedilmiş. | E7: 1. Ödeme adımında kayıtlı kartı seç | F7: PayTR ile uyumlu şekilde kullanılır; CVV istenebilir. | H7: Beklemede | L7: Orta
A8: W07-005 | B8: W07 | C8: Sipariş onayı sonrası yönlendirme | D8: Ödeme başarılı. | E8: 1. PayTR sonrası yönlendirmeyi bekle | F8: /checkout/success sayfası açılır; sipariş no, e-posta bildirimi gelir. | H8: Beklemede | L8: Orta
A9: W07-006 | B9: W07 | C9: İndirim kuponunu checkout'ta uygulama | D9: Aktif kupon. | E9: 1. Kupon alanına kodu gir, Uygula | F9: İndirim toplamdan düşülür; kullanım limiti varsa kontrol edilir. | H9: Beklemede | L9: Orta
A10: W07-007 | B10: W07 | C10: Üyelik tier indirimi otomatik uygulanır | D10: Premium/Business üye. | E10: 1. Sipariş özetini incele | F10: Tier indirimi açıkça gösterilir. | H10: Beklemede | L10: Orta
A13: Bu sayfadaki tüm senaryolar test edilmiş ve sonuçlar yukarıda işaretlenmiştir.
A14: Test Eden (Tarodan) | D14: Tarih | G14: Onaylayan (Müşteri) | J14: Tarih

Sheet W08 - Ödeme PayTR
A1: W08 — PayTR Ödeme Akışı
A2: iFrame ödeme, 3D Secure, başarısız ödeme, callback.
A3: Test ID | B3: Modül / Sayfa | C3: Senaryo / Test Adı | D3: Önkoşullar | E3: Adımlar (numaralı) | F3: Beklenen Sonuç | G3: Gerçek Sonuç | H3: Durum | I3: Test Eden | J3: Test Tarihi | K3: Tarayıcı / Cihaz | L3: Öncelik | M3: Notlar / Hata Linki
A4: W08-001 | B4: W08 | C4: PayTR iFrame yüklenmesi | D4: Sipariş onaylandı. | E4: 1. Onay sonrası iFrame'i bekle | F4: PayTR iFrame sorunsuz açılır; sipariş tutarı görünür. | H4: Beklemede | L4: Kritik
A5: W08-002 | B5: W08 | C5: Geçerli test kartı ile ödeme | D5: Test ortamı, PayTR test kartı. | E5: 1. Kart bilgilerini gir 2. 3D Secure adımını tamamla | F5: Başarılı; /checkout/success'e yönlendirme; webhook'la sipariş 'preparing' olur. | H5: Beklemede | L5: Kritik
A6: W08-003 | B6: W08 | C6: Yetersiz bakiye / ret kart | D6: Test ret kartı. | E6: 1. Reddedilen kart ile dene | F6: /payment/fail veya hata; sipariş pending; sepet korunur. | H6: Beklemede | L6: Orta
A7: W08-004 | B7: W08 | C7: 3D Secure'da kullanıcı iptal | D7: — | E7: 1. Banka SMS'inde iptal et | F7: Hata; tekrar dene seçeneği; stok rezervi geri verilir. | H7: Beklemede | L7: Orta
A8: W08-005 | B8: W08 | C8: iFrame ortasında pencere kapatma | D8: Ödeme başlatıldı. | E8: 1. Tarayıcı sekmesini kapat | F8: Sipariş 15 dk pending kalır; otomatik iptal cron'u tetiklenir; stok serbest bırakılır. | H8: Beklemede | L8: Orta
A9: W08-006 | B9: W08 | C9: Callback hash doğrulama (negatif) | D9: Manuel webhook hash bozuk. | E9: 1. Backend manuel test ile geçersiz callback gönder | F9: Webhook reddedilir; sipariş güncellenmez; log'a düşer. | H9: Beklemede | L9: Kritik
A10: W08-007 | B10: W08 | C10: Ödeme retry akışı | D10: Bir kez başarısız ödeme. | E10: 1. Sepete dön, tekrar checkout | F10: Yeni ödeme başlatılabilir; eski payment failed olarak kalır. | H10: Beklemede | L10: Orta
A11: W08-008 | B11: W08 | C11: Ödeme timeout reconciliation | D11: Pending ödeme 15+ dk. | E11: 1. Cron'un sonucunu bekle | F11: Sistem PayTR API'den durumu sorgular; sonuca göre günceller. | H11: Beklemede | L11: Orta
A14: Bu sayfadaki tüm senaryolar test edilmiş ve sonuçlar yukarıda işaretlenmiştir.
A15: Test Eden (Tarodan) | D15: Tarih | G15: Onaylayan (Müşteri) | J15: Tarih

Sheet W09 - Siparişlerim Listesi
A1: W09 — Siparişlerim (Alıcı) Listesi
A2: Sipariş listesi, filtre, durum rozetleri, satıcı/alıcı sekmesi.
A3: Test ID | B3: Modül / Sayfa | C3: Senaryo / Test Adı | D3: Önkoşullar | E3: Adımlar (numaralı) | F3: Beklenen Sonuç | G3: Gerçek Sonuç | H3: Durum | I3: Test Eden | J3: Test Tarihi | K3: Tarayıcı / Cihaz | L3: Öncelik | M3: Notlar / Hata Linki
A4: W09-001 | B4: W09 | C4: Sipariş listesi yükleme | D4: Üye, en az 1 sipariş. | E4: 1. /orders aç | F4: Tüm siparişler tarihe göre listelenir; durum rozetleri renkli. | H4: Beklemede | L4: Kritik
A5: W09-002 | B5: W09 | C5: Alıcı / Satıcı sekme geçişi | D5: Hem alıcı hem satıcı kullanıcı. | E5: 1. Sekmeleri değiştir | F5: Liste filtrelenir; sayaçlar doğru. | H5: Beklemede | L5: Orta
A6: W09-003 | B6: W09 | C6: Durum filtresi | D6: Farklı durumlu siparişler. | E6: 1. Filtre dropdown'undan 'Kargoda' seç | F6: Sadece kargoda olanlar listelenir. | H6: Beklemede | L6: Orta
A7: W09-004 | B7: W09 | C7: Sipariş ara (no veya ürün adı) | D7: — | E7: 1. Arama kutusuna sipariş no yaz | F7: İlgili sipariş(ler) bulunur. | H7: Beklemede | L7: Orta
A8: W09-005 | B8: W09 | C8: Boş liste durumu (yeni hesap) | D8: Hiç sipariş yok. | E8: 1. /orders aç | F8: “Henüz siparişiniz yok” + alışverişe başla butonu. | H8: Beklemede | L8: Orta
A9: W09-006 | B9: W09 | C9: Sayfalama veya sonsuz scroll | D9: Çok sipariş. | E9: 1. Aşağı scroll / sonraki sayfa | F9: Eski siparişler yüklenir; performans kabul edilebilir. | H9: Beklemede | L9: Orta
A12: Bu sayfadaki tüm senaryolar test edilmiş ve sonuçlar yukarıda işaretlenmiştir.
A13: Test Eden (Tarodan) | D13: Tarih | G13: Onaylayan (Müşteri) | J13: Tarih

Sheet W10 - Sipariş Detay & Takip
A1: W10 — Sipariş Detayı, Kargo Takibi, Yorum
A2: Sipariş timeline, kargo takip, satıcıya mesaj, yorum yazma.
A3: Test ID | B3: Modül / Sayfa | C3: Senaryo / Test Adı | D3: Önkoşullar | E3: Adımlar (numaralı) | F3: Beklenen Sonuç | G3: Gerçek Sonuç | H3: Durum | I3: Test Eden | J3: Test Tarihi | K3: Tarayıcı / Cihaz | L3: Öncelik | M3: Notlar / Hata Linki
A4: W10-001 | B4: W10 | C4: Sipariş detay sayfası | D4: Aktif bir sipariş. | E4: 1. /orders/[id] aç | F4: Ürünler, kargo, ödeme, satıcı, durum timeline eksiksiz. | H4: Beklemede | L4: Kritik
A5: W10-002 | B5: W10 | C5: Durum timeline | D5: — | E5: 1. Timeline'ı incele | F5: Durum geçişleri kronolojik, tarih/saat ile görünür. | H5: Beklemede | L5: Orta
A6: W10-003 | B6: W10 | C6: Kargo takip linkine tıklama | D6: Kargolanmış sipariş, tracking no var. | E6: 1. 'Kargoyu Takip Et'e bas | F6: Kargo şirketi sitesi açılır veya gömülü iframe; doğru tracking no. | H6: Beklemede | L6: Orta
A7: W10-004 | B7: W10 | C7: Sipariş özeti PDF / yazdırma | D7: — | E7: 1. 'Yazdır' butonuna bas | F7: Yazdırılabilir özet açılır. | H7: Beklemede | L7: Orta
A8: W10-005 | B8: W10 | C8: Satıcıya mesaj atma | D8: — | E8: 1. 'Satıcıya Mesaj' linkine bas | F8: /messages thread'i açılır, sipariş bağlamı eklenir. | H8: Beklemede | L8: Orta
A9: W10-006 | B9: W10 | C9: Teslim alındıktan sonra yorum yazma | D9: Sipariş 'delivered'. | E9: 1. 'Yorum Yap'a bas, yıldız ver, metin yaz, gönder | F9: Yorum gönderilir; satıcının ürün sayfasında moderasyon sonrası görünür. | H9: Beklemede | L9: Orta
A10: W10-007 | B10: W10 | C10: Fatura indirme | D10: Fatura oluşturulmuş. | E10: 1. 'Fatura İndir' linkine bas | F10: PDF açılır/indirir; vergi, KDV, kalemler doğru. | H10: Beklemede | L10: Orta
A13: Bu sayfadaki tüm senaryolar test edilmiş ve sonuçlar yukarıda işaretlenmiştir.
A14: Test Eden (Tarodan) | D14: Tarih | G14: Onaylayan (Müşteri) | J14: Tarih

Sheet W11 - Sipariş İptal
A1: W11 — Sipariş İptal Akışı
A2: Kargolanmadan önce/sonra iptal, satıcı onayı, otomatik iade.
A3: Test ID | B3: Modül / Sayfa | C3: Senaryo / Test Adı | D3: Önkoşullar | E3: Adımlar (numaralı) | F3: Beklenen Sonuç | G3: Gerçek Sonuç | H3: Durum | I3: Test Eden | J3: Test Tarihi | K3: Tarayıcı / Cihaz | L3: Öncelik | M3: Notlar / Hata Linki
A4: W11-001 | B4: W11 | C4: Ödeme bekleyen siparişi iptal | D4: Sipariş 'pending_payment'. | E4: 1. Detayda 'Siparişi İptal Et'e bas | F4: Sipariş anında iptal; stok serbest; herhangi bir ücret yok. | H4: Beklemede | L4: Yüksek
A5: W11-002 | B5: W11 | C5: Hazırlanıyor durumunda iptal isteği | D5: Sipariş 'preparing'. | E5: 1. İptal İsteği Oluştur | F5: Satıcıya iptal talebi gider; durum 'cancel_requested'. | H5: Beklemede | L5: Orta
A6: W11-003 | B6: W11 | C6: Satıcı iptal talebini kabul | D6: Cancel-requested sipariş. | E6: 1. (Satıcı tarafında) Onayla | F6: Sipariş iptal; PayTR otomatik refund tetiklenir; alıcıya mail. | H6: Beklemede | L6: Orta
A7: W11-004 | B7: W11 | C7: Satıcı iptal talebini reddetti | D7: — | E7: 1. Satıcı reddeder | F7: Talep kapanır; alıcıya bilgi maili; iade için teslimat sonrasını beklemesi gerekir. | H7: Beklemede | L7: Orta
A8: W11-005 | B8: W11 | C8: Kargolanmış sipariş için iptal denemesi | D8: Sipariş 'shipped'. | E8: 1. İptal butonu aramak | F8: İptal mevcut değil; 'İade Talebi' yönlendirmesi gösterilir. | H8: Beklemede | L8: Yüksek
A9: W11-006 | B9: W11 | C9: İptal sonrası mail bildirimi | D9: — | E9: 1. İptali tamamla | F9: Hem alıcı hem satıcıya iptal maili gider. | H9: Beklemede | L9: Orta
A12: Bu sayfadaki tüm senaryolar test edilmiş ve sonuçlar yukarıda işaretlenmiştir.
A13: Test Eden (Tarodan) | D13: Tarih | G13: Onaylayan (Müşteri) | J13: Tarih

Sheet W12 - İade Talebi
A1: W12 — İade ve Değişim Akışı
A2: Talep oluşturma, kanıt yükleme, satıcı onayı, kargo, refund.
A3: Test ID | B3: Modül / Sayfa | C3: Senaryo / Test Adı | D3: Önkoşullar | E3: Adımlar (numaralı) | F3: Beklenen Sonuç | G3: Gerçek Sonuç | H3: Durum | I3: Test Eden | J3: Test Tarihi | K3: Tarayıcı / Cihaz | L3: Öncelik | M3: Notlar / Hata Linki
A4: W12-001 | B4: W12 | C4: İade talebi oluşturma (delivered) | D4: Teslim edilmiş sipariş, 14 gün içinde. | E4: 1. /orders/[id] aç 2. 'İade Talebi Aç'a bas 3. Sebep seç, açıklama yaz, fotoğraf yükle, gönder | F4: Talep oluşur; satıcıya bildirim/mail; durum 'pending_review'. | H4: Beklemede | L4: Kritik
A5: W12-002 | B5: W12 | C5: Hasar/tanım uyumsuzluğu için fotoğraf zorunluluğu | D5: Sebep 'hasarlı' seçildi. | E5: 1. Fotoğraf yüklemeden gönderme deneme | F5: Form geçmez; fotoğraf zorunlu uyarısı. | H5: Beklemede | L5: Orta
A6: W12-003 | B6: W12 | C6: İade taleplerim listesi | D6: — | E6: 1. /refund-requests aç | F6: Tüm talepler listelenir; durum filtreleri çalışır. | H6: Beklemede | L6: Orta
A7: W12-004 | B7: W12 | C7: Satıcı iadeyi onayladı — kargo bilgisi | D7: Durum 'approved'. | E7: 1. Detayı aç | F7: İade kargo etiketi/yönergeleri görünür; takip no girilebilir. | H7: Beklemede | L7: Orta
A8: W12-005 | B8: W12 | C8: İade kargo gönderme | D8: — | E8: 1. Tracking no gir, gönder | F8: Durum 'return_in_transit'; satıcıya bilgi. | H8: Beklemede | L8: Orta
A9: W12-006 | B9: W12 | C9: Satıcı iade ürünü teslim aldı | D9: — | E9: 1. Satıcı tarafında 'Teslim Aldım' işaretle | F9: Durum 'received'; refund cron'u tetiklenir. | H9: Beklemede | L9: Orta
A10: W12-007 | B10: W12 | C10: Refund tamamlandı (PayTR) | D10: Refund işlendi. | E10: 1. Mail kontrol | F10: “Para iadeniz yapıldı” maili; durum 'refunded'; tutar PayTR refund'la geri. | H10: Beklemede | L10: Orta
A11: W12-008 | B11: W12 | C11: İade talebi reddetildi | D11: Satıcı reddetti. | E11: 1. Detayı aç | F11: Sebep gösterilir; itiraz/destek yönlendirmesi. | H11: Beklemede | L11: Orta
A12: W12-009 | B12: W12 | C12: İade süresi dolmuş | D12: Teslimat üzerinden 14+ gün. | E12: 1. İade Talebi açmaya çalış | F12: Buton disabled; süre dolmuş bilgisi. | H12: Beklemede | L12: Orta
A13: W12-010 | B13: W12 | C13: Trade (takas) iadesi nakit refund | D13: Cash diff'li takasta iade kabul. | E13: 1. Takas iadesini başlat | F13: Sadece nakit fark refund edilir; takas durumu güncellenir. | H13: Beklemede | L13: Yüksek
A16: Bu sayfadaki tüm senaryolar test edilmiş ve sonuçlar yukarıda işaretlenmiştir.
A17: Test Eden (Tarodan) | D17: Tarih | G17: Onaylayan (Müşteri) | J17: Tarih

Sheet W13 - Profil & Ayarlar
A1: W13 — Profil, Adres, Şifre, Ödeme Yöntemleri
A2: Kullanıcı kendi hesabını yönetir.
A3: Test ID | B3: Modül / Sayfa | C3: Senaryo / Test Adı | D3: Önkoşullar | E3: Adımlar (numaralı) | F3: Beklenen Sonuç | G3: Gerçek Sonuç | H3: Durum | I3: Test Eden | J3: Test Tarihi | K3: Tarayıcı / Cihaz | L3: Öncelik | M3: Notlar / Hata Linki
A4: W13-001 | B4: W13 | C4: Profil sayfası açılışı | D4: Üye giriş. | E4: 1. /profile aç | F4: Avatar, ad, e-posta, telefon, üyelik, istatistikler görünür. | H4: Beklemede | L4: Orta
A5: W13-002 | B5: W13 | C5: Avatar yükleme | D5: — | E5: 1. Avatar resmini değiştir, kaydet | F5: Resim yüklenir, profil ve yorumlarda görünür. | H5: Beklemede | L5: Orta
A6: W13-003 | B6: W13 | C6: Ad/Soyad/Bio güncelleme | D6: — | E6: 1. Edit profil → bilgileri değiştir, kaydet | F6: Değişiklikler kalıcı; refresh sonrası korunur. | H6: Beklemede | L6: Orta
A7: W13-004 | B7: W13 | C7: Adres ekleme/düzenleme/silme | D7: — | E7: 1. /profile/addresses aç 2. Yeni adres ekle, düzenle, sil | F7: Tüm CRUD çalışır; varsayılan adres seçilebilir. | H7: Beklemede | L7: Orta
A8: W13-005 | B8: W13 | C8: Şifre değiştir | D8: — | E8: 1. /profile/change-password 2. Eski şifre + yeni şifre x2 gir, kaydet | F8: Başarılı; yeni şifre ile login çalışır; tüm oturumlar opsiyonel sonlanır. | H8: Beklemede | L8: Yüksek
A9: W13-006 | B9: W13 | C9: Eski şifre yanlış | D9: — | E9: 1. Eski şifreyi yanlış gir | F9: Hata; değişiklik kaydedilmez. | H9: Beklemede | L9: Orta
A10: W13-007 | B10: W13 | C10: Ödeme yöntemleri yönetimi | D10: — | E10: 1. /profile/payments aç 2. Kayıtlı kartları gör, yenisini ekle, sil | F10: Tokenize edilmiş kart bilgileri görünür; CVV asla saklanmaz. | H10: Beklemede | L10: Orta
A11: W13-008 | B11: W13 | C11: İndirim kuponları listesi | D11: — | E11: 1. /profile/discounts aç | F11: Aktif/kullanılmış kuponlar; kopyala butonu çalışır. | H11: Beklemede | L11: Orta
A12: W13-009 | B12: W13 | C12: İstatistikler | D12: — | E12: 1. /profile/statistics aç | F12: Satış, görüntülenme, beğeni metrikleri görünür. | H12: Beklemede | L12: Orta
A13: W13-010 | B13: W13 | C13: Kurumsal hesap detayları | D13: Kurumsal kullanıcı. | E13: 1. /profile/business aç | F13: Şirket, vergi, fatura bilgileri görüntü/düzenleme. | H13: Beklemede | L13: Orta
A14: W13-011 | B14: W13 | C14: İlanlarım sayfası | D14: Satıcı. | E14: 1. /profile/listings aç | F14: Aktif/satılan/silinmiş sekmeleri çalışır; düzenleme/silme/devre dışı. | H14: Beklemede | L14: Orta
A15: W13-012 | B15: W13 | C15: Hesabı sil / dondur | D15: — | E15: 1. Ayarlardan 'Hesabımı Sil'e bas | F15: Onay modali; KVKK gereği veri silme/anonimleştirme süreci başlar. | H15: Beklemede | L15: Yüksek
A18: Bu sayfadaki tüm senaryolar test edilmiş ve sonuçlar yukarıda işaretlenmiştir.
A19: Test Eden (Tarodan) | D19: Tarih | G19: Onaylayan (Müşteri) | J19: Tarih

Sheet W14 - Satıcı İlan Yönetimi
A1: W14 — Satıcı: İlan Oluşturma ve Yönetimi
A2: Yeni ilan, görsel yükleme, kategori, fiyat, üyelik limit.
A3: Test ID | B3: Modül / Sayfa | C3: Senaryo / Test Adı | D3: Önkoşullar | E3: Adımlar (numaralı) | F3: Beklenen Sonuç | G3: Gerçek Sonuç | H3: Durum | I3: Test Eden | J3: Test Tarihi | K3: Tarayıcı / Cihaz | L3: Öncelik | M3: Notlar / Hata Linki
A4: W14-001 | B4: W14 | C4: Yeni ilan oluşturma (satıcı) | D4: Onaylı satıcı. | E4: 1. /listings/new aç 2. Kategori, marka, başlık, açıklama, fiyat, görsel yükle 3. Yayınla | F4: İlan moderasyon kuyruğuna düşer; satıcıya bilgi maili. | H4: Beklemede | L4: Kritik
A5: W14-002 | B5: W14 | C5: Görsel boyut/format kontrolü | D5: — | E5: 1. 10MB üstü veya .exe yüklemeye çalış | F5: Reddedilir; hata mesajı gösterilir. | H5: Beklemede | L5: Orta
A6: W14-003 | B6: W14 | C6: Sürükle-bırak görsel sıralama | D6: Çoklu görsel. | E6: 1. Görselleri yeniden sırala | F6: Sıralama kaydedilir; ilk görsel kapak olur. | H6: Beklemede | L6: Orta
A7: W14-004 | B7: W14 | C7: Üyelik ilan limiti aşımı | D7: Free tier, limit dolmuş. | E7: 1. Yeni ilan denemesi | F7: “Limitiniz doldu, yükseltin” uyarısı + Premium CTA. | H7: Beklemede | L7: Orta
A8: W14-005 | B8: W14 | C8: Taslak olarak kaydet | D8: — | E8: 1. Form yarıda 'Taslak Kaydet' | F8: İlan taslak olarak listelenir; sonradan düzenlenebilir. | H8: Beklemede | L8: Orta
A9: W14-006 | B9: W14 | C9: İlan düzenleme | D9: Aktif ilan. | E9: 1. İlanı düzenle, fiyat değiştir, kaydet | F9: Değişiklikler anında yansır; sepetteki kullanıcılar uyarılır. | H9: Beklemede | L9: Orta
A10: W14-007 | B10: W14 | C10: İlanı devre dışı bırakma | D10: — | E10: 1. 'Pasif Yap'a bas | F10: İlan listelerde görünmez; satıcı paneline pasif olarak gelir. | H10: Beklemede | L10: Orta
A11: W14-008 | B11: W14 | C11: İlanı silme | D11: — | E11: 1. 'Sil'e bas, onayla | F11: İlan kalıcı silinir veya soft-delete; sipariş geçmişi kalır. | H11: Beklemede | L11: Orta
A12: W14-009 | B12: W14 | C12: Reddedilen ilan akışı | D12: Admin reddetti. | E12: 1. Mail oku, ilanı düzelt, tekrar yayınla | F12: Ret sebebi maile düşer; düzeltip tekrar moderasyona gönderilir. | H12: Beklemede | L12: Orta
A15: Bu sayfadaki tüm senaryolar test edilmiş ve sonuçlar yukarıda işaretlenmiştir.
A16: Test Eden (Tarodan) | D16: Tarih | G16: Onaylayan (Müşteri) | J16: Tarih

Sheet W15 - Satıcı Sipariş Yönetimi
A1: W15 — Satıcı: Sipariş İşleme ve Kargolama
A2: Satıcının sipariş alıp kargolaması, payout takibi.
A3: Test ID | B3: Modül / Sayfa | C3: Senaryo / Test Adı | D3: Önkoşullar | E3: Adımlar (numaralı) | F3: Beklenen Sonuç | G3: Gerçek Sonuç | H3: Durum | I3: Test Eden | J3: Test Tarihi | K3: Tarayıcı / Cihaz | L3: Öncelik | M3: Notlar / Hata Linki
A4: W15-001 | B4: W15 | C4: Satıcı dashboard | D4: Satıcı, sipariş var. | E4: 1. /seller/dashboard aç | F4: İstatistikler, bekleyen siparişler, performans görünür. | H4: Beklemede | L4: Orta
A5: W15-002 | B5: W15 | C5: Yeni sipariş bildirimi | D5: Yeni sipariş geldi. | E5: 1. Bildirim maili ve in-app bildirim kontrol | F5: Mail + in-app + push tetiklenir; dashboard'da 'bekliyor' sayacı artar. | H5: Beklemede | L5: Kritik
A6: W15-003 | B6: W15 | C6: Sipariş detayı (satıcı) | D6: — | E6: 1. /seller/orders/[id] aç | F6: Kargo girişi, alıcı bilgisi, ödeme özeti, kargo deadline görünür. | H6: Beklemede | L6: Orta
A7: W15-004 | B7: W15 | C7: Kargo bilgisi girme | D7: — | E7: 1. Kargo şirketi seç, takip no gir, kaydet | F7: Sipariş 'shipped' olur; alıcıya tracking maili gider. | H7: Beklemede | L7: Kritik
A8: W15-005 | B8: W15 | C8: Kargo deadline geçme uyarısı | D8: Sipariş üzerinden 3 iş günü geçti. | E8: 1. Dashboard kontrol | F8: Uyarı maili; satıcı performans skoru etkilenir. | H8: Beklemede | L8: Orta
A9: W15-006 | B9: W15 | C9: Kargo deadline geçti — otomatik iptal | D9: Çok geç kalındı. | E9: 1. Cron tetiklenmesini bekle | F9: Sipariş otomatik iptal; alıcıya iade; satıcıya bildirim. | H9: Beklemede | L9: Orta
A10: W15-007 | B10: W15 | C10: Banka hesabı eklenmemiş — payout uyarısı | D10: Yeni satıcı, IBAN yok. | E10: 1. Dashboard kontrol | F10: “Banka bilgilerini ekleyin” uyarısı; payout pending. | H10: Beklemede | L10: Orta
A11: W15-008 | B11: W15 | C11: Payout başarılı | D11: Teslimat + 7 gün geçti, IBAN var. | E11: 1. Payout cron tetiklenir | F11: Payout 'completed'; mail bildirimi; bakiye 0. | H11: Beklemede | L11: Orta
A14: Bu sayfadaki tüm senaryolar test edilmiş ve sonuçlar yukarıda işaretlenmiştir.
A15: Test Eden (Tarodan) | D15: Tarih | G15: Onaylayan (Müşteri) | J15: Tarih

Sheet W16 - Teklifler
A1: W16 — Teklif (Offer) Akışı
A2: Teklif ver, karşı teklif, kabul/red, expire, ödeme.
A3: Test ID | B3: Modül / Sayfa | C3: Senaryo / Test Adı | D3: Önkoşullar | E3: Adımlar (numaralı) | F3: Beklenen Sonuç | G3: Gerçek Sonuç | H3: Durum | I3: Test Eden | J3: Test Tarihi | K3: Tarayıcı / Cihaz | L3: Öncelik | M3: Notlar / Hata Linki
